<?xml version="1.0" ?>
<!-- =================================================================================== -->
<!-- |    This document was autogenerated by xacro from robot_version1.xacro           | -->
<!-- |    EDITING THIS FILE BY HAND IS NOT RECOMMENDED                                 | -->
<!-- =================================================================================== -->
<robot name="robot_version1">
  <material name="silver">
    <color rgba="0.700 0.700 0.700 1.000"/>
  </material>
  <!--
  <transmission name="motor1_tran">
    <type>transmission_interface/SimpleTransmission</type>
    <joint name="motor1">
      <hardwareInterface>hardware_interface/EffortJointInterface</hardwareInterface>
    </joint>
    <actuator name="motor1_actr">
      <hardwareInterface>hardware_interface/EffortJointInterface</hardwareInterface>
      <mechanicalReduction>1</mechanicalReduction>
    </actuator>
  </transmission>
  <transmission name="motor2_tran">
    <type>transmission_interface/SimpleTransmission</type>
    <joint name="motor2">
      <hardwareInterface>hardware_interface/EffortJointInterface</hardwareInterface>
    </joint>
    <actuator name="motor2_actr">
      <hardwareInterface>hardware_interface/EffortJointInterface</hardwareInterface>
      <mechanicalReduction>1</mechanicalReduction>
    </actuator>
  </transmission>
  <transmission name="motor3_tran">
    <type>transmission_interface/SimpleTransmission</type>
    <joint name="motor3">
      <hardwareInterface>hardware_interface/EffortJointInterface</hardwareInterface>
    </joint>
    <actuator name="motor3_actr">
      <hardwareInterface>hardware_interface/EffortJointInterface</hardwareInterface>
      <mechanicalReduction>1</mechanicalReduction>
    </actuator>
  </transmission>
  <transmission name="motor4_tran">
    <type>transmission_interface/SimpleTransmission</type>
    <joint name="motor4">
      <hardwareInterface>hardware_interface/EffortJointInterface</hardwareInterface>
    </joint>
    <actuator name="motor4_actr">
      <hardwareInterface>hardware_interface/EffortJointInterface</hardwareInterface>
      <mechanicalReduction>1</mechanicalReduction>
    </actuator>
  </transmission>
  <transmission name="motor5_tran">
    <type>transmission_interface/SimpleTransmission</type>
    <joint name="motor5">
      <hardwareInterface>hardware_interface/EffortJointInterface</hardwareInterface>
    </joint>
    <actuator name="motor5_actr">
      <hardwareInterface>hardware_interface/EffortJointInterface</hardwareInterface>
      <mechanicalReduction>1</mechanicalReduction>
    </actuator>
  </transmission>
  <transmission name="motor6_tran">
    <type>transmission_interface/SimpleTransmission</type>
    <joint name="motor6">
      <hardwareInterface>hardware_interface/EffortJointInterface</hardwareInterface>
    </joint>
    <actuator name="motor6_actr">
      <hardwareInterface>hardware_interface/EffortJointInterface</hardwareInterface>
      <mechanicalReduction>1</mechanicalReduction>
    </actuator>
  </transmission>
  <transmission name="Corredera9_tran">
    <type>transmission_interface/SimpleTransmission</type>
    <joint name="Corredera9">
      <hardwareInterface>hardware_interface/EffortJointInterface</hardwareInterface>
    </joint>
    <actuator name="Corredera9_actr">
      <hardwareInterface>hardware_interface/EffortJointInterface</hardwareInterface>
      <mechanicalReduction>1</mechanicalReduction>
    </actuator>
  </transmission>
  <transmission name="Corredera10_tran">
    <type>transmission_interface/SimpleTransmission</type>
    <joint name="Corredera10">
      <hardwareInterface>hardware_interface/EffortJointInterface</hardwareInterface>
    </joint>
    <actuator name="Corredera10_actr">
      <hardwareInterface>hardware_interface/EffortJointInterface</hardwareInterface>
      <mechanicalReduction>1</mechanicalReduction>
    </actuator>
  </transmission> -->
  
  <gazebo>
    <plugin filename="libgazebo_ros_control.so" name="control"/>
  </gazebo>
  <gazebo reference="base_link">
    <material>Gazebo/Silver</material>
    <mu1>0.2</mu1>
    <mu2>0.2</mu2>
    <self_collide>true</self_collide>
    <gravity>true</gravity>
  </gazebo>
  <gazebo reference="link1_1">
    <material>Gazebo/Silver</material>
    <mu1>0.2</mu1>
    <mu2>0.2</mu2>
    <self_collide>true</self_collide>
  </gazebo>
  <gazebo reference="link2_1">
    <material>Gazebo/Silver</material>
    <mu1>0.2</mu1>
    <mu2>0.2</mu2>
    <self_collide>true</self_collide>
  </gazebo>
  <gazebo reference="link3_1">
    <material>Gazebo/Silver</material>
    <mu1>0.2</mu1>
    <mu2>0.2</mu2>
    <self_collide>true</self_collide>
  </gazebo>
  <gazebo reference="link4_1">
    <material>Gazebo/Silver</material>
    <mu1>0.2</mu1>
    <mu2>0.2</mu2>
    <self_collide>true</self_collide>
  </gazebo>
  <gazebo reference="link5_1">
    <material>Gazebo/Silver</material>
    <mu1>0.2</mu1>
    <mu2>0.2</mu2>
    <self_collide>true</self_collide>
  </gazebo>
  <gazebo reference="link6_1">
    <material>Gazebo/Silver</material>
    <mu1>0.2</mu1>
    <mu2>0.2</mu2>
    <self_collide>true</self_collide>
  </gazebo>
  <gazebo reference="gripper2_1">
    <material>Gazebo/Silver</material>
    <mu1>0.2</mu1>
    <mu2>0.2</mu2>
    <self_collide>true</self_collide>
  </gazebo>
  <gazebo reference="griper1_1">
    <material>Gazebo/Silver</material>
    <mu1>0.2</mu1>
    <mu2>0.2</mu2>
    <self_collide>true</self_collide>
  </gazebo>
  <link name="base_link">
    <inertial>
      <origin rpy="0 0 0" xyz="-1.1580046200244058e-17 0.024999999999999994 5.790023100122029e-18"/>
      <mass value="3.082687791334984"/>
      <inertia ixx="0.002569" ixy="-0.0" ixz="-0.0" iyy="0.003853" iyz="-0.0" izz="0.002569"/>
    </inertial>
    <visual>
      <origin rpy="0 0 0" xyz="0 0 0"/>
      <geometry>
        <mesh filename="file:///home/user/proyecto_ws/src/proyecto_final/meshes/base_link.stl" scale="0.001 0.001 0.001"/>
      </geometry>
      <material name="silver"/>
    </visual>
    <collision>
      <origin rpy="0 0 0" xyz="0 0 0"/>
      <geometry>
        <mesh filename="file:///home/user/proyecto_ws/src/proyecto_final/meshes/base_link.stl" scale="0.001 0.001 0.001"/>
      </geometry>
    </collision>
  </link>
  <link name="link1_1">
    <inertial>
      <origin rpy="0 0 0" xyz="9.008917649016016e-18 0.0437607595854386 0.035413080138187114"/>
      <mass value="7.924962450619459"/>
      <inertia ixx="0.016525" ixy="0.0" ixz="0.0" iyy="0.016428" iyz="-0.002169" izz="0.010003"/>
    </inertial>
    <visual>
      <origin rpy="0 0 0" xyz="-0.0 -0.05 -0.0"/>
      <geometry>
        <mesh filename="file:///home/user/proyecto_ws/src/proyecto_final/meshes/link1_1.stl" scale="0.001 0.001 0.001"/>
      </geometry>
      <material name="silver"/>
    </visual>
    <collision>
      <origin rpy="0 0 0" xyz="-0.0 -0.05 -0.0"/>
      <geometry>
        <mesh filename="file:///home/user/proyecto_ws/src/proyecto_final/meshes/link1_1.stl" scale="0.001 0.001 0.001"/>
      </geometry>
    </collision>
  </link>
  <link name="link2_1">
    <inertial>
      <origin rpy="0 0 0" xyz="-8.314822887740735e-18 0.016342334380787568 0.12980540062847232"/>
      <mass value="17.173025824624403"/>
      <inertia ixx="0.10519" ixy="-0.0" ixz="0.0" iyy="0.093316" iyz="-0.020118" izz="0.03334"/>
    </inertial>
    <visual>
      <origin rpy="0 0 0" xyz="0.0 -0.1 -0.1"/>
      <geometry>
        <mesh filename="file:///home/user/proyecto_ws/src/proyecto_final/meshes/link2_1.stl" scale="0.001 0.001 0.001"/>
      </geometry>
      <material name="silver"/>
    </visual>
    <collision>
      <origin rpy="0 0 0" xyz="0.0 -0.1 -0.1"/>
      <geometry>
        <mesh filename="file:///home/user/proyecto_ws/src/proyecto_final/meshes/link2_1.stl" scale="0.001 0.001 0.001"/>
      </geometry>
    </collision>
  </link>
  <link name="link3_1">
    <inertial>
      <origin rpy="0 0 0" xyz="1.013394198499686e-17 0.1027347532259798 0.01991771451421981"/>
      <mass value="14.090338033289418"/>
      <inertia ixx="0.060349" ixy="-0.0" ixz="0.0" iyy="0.028484" iyz="-0.013683" izz="0.049478"/>
    </inertial>
    <visual>
      <origin rpy="0 0 0" xyz="-0.0 -0.2 -0.3"/>
      <geometry>
        <mesh filename="file:///home/user/proyecto_ws/src/proyecto_final/meshes/link3_1.stl" scale="0.001 0.001 0.001"/>
      </geometry>
      <material name="silver"/>
    </visual>
    <collision>
      <origin rpy="0 0 0" xyz="-0.0 -0.2 -0.3"/>
      <geometry>
        <mesh filename="file:///home/user/proyecto_ws/src/proyecto_final/meshes/link3_1.stl" scale="0.001 0.001 0.001"/>
      </geometry>
    </collision>
  </link>
  <link name="link4_1">
    <inertial>
      <origin rpy="0 0 0" xyz="0.0 0.016342334380787638 0.12980540062847234"/>
      <mass value="17.173025824624403"/>
      <inertia ixx="0.10519" ixy="0.0" ixz="0.0" iyy="0.093316" iyz="-0.020118" izz="0.03334"/>
    </inertial>
    <visual>
      <origin rpy="0 0 0" xyz="0.0 -0.35 -0.4"/>
      <geometry>
        <mesh filename="file:///home/user/proyecto_ws/src/proyecto_final/meshes/link4_1.stl" scale="0.001 0.001 0.001"/>
      </geometry>
      <material name="silver"/>
    </visual>
    <collision>
      <origin rpy="0 0 0" xyz="0.0 -0.35 -0.4"/>
      <geometry>
        <mesh filename="file:///home/user/proyecto_ws/src/proyecto_final/meshes/link4_1.stl" scale="0.001 0.001 0.001"/>
      </geometry>
    </collision>
  </link>
  <link name="link5_1">
    <inertial>
      <origin rpy="0 0 0" xyz="0.0 0.11444820806225936 0.003509195158339584"/>
      <mass value="14.090338033289422"/>
      <inertia ixx="0.071182" ixy="-0.0" ixz="0.0" iyy="0.017844" iyz="-0.004648" izz="0.07095"/>
    </inertial>
    <visual>
      <origin rpy="0 0 0" xyz="-0.0 -0.45 -0.6"/>
      <geometry>
        <mesh filename="file:///home/user/proyecto_ws/src/proyecto_final/meshes/link5_1.stl" scale="0.001 0.001 0.001"/>
      </geometry>
      <material name="silver"/>
    </visual>
    <collision>
      <origin rpy="0 0 0" xyz="-0.0 -0.45 -0.6"/>
      <geometry>
        <mesh filename="file:///home/user/proyecto_ws/src/proyecto_final/meshes/link5_1.stl" scale="0.001 0.001 0.001"/>
      </geometry>
    </collision>
  </link>
  <link name="link6_1">
    <inertial>
      <origin rpy="0 0 0" xyz="1.7953246794872857e-11 3.3854696823709673e-10 0.02603270456929907"/>
      <mass value="3.1925877913349834"/>
      <inertia ixx="0.002669" ixy="0.0" ixz="-0.0" iyy="0.00271" iyz="-0.0" izz="0.003902"/>
    </inertial>
    <visual>
      <origin rpy="0 0 0" xyz="0.0 -0.65 -0.65"/>
      <geometry>
        <mesh filename="file:///home/user/proyecto_ws/src/proyecto_final/meshes/link6_1.stl" scale="0.001 0.001 0.001"/>
      </geometry>
      <material name="silver"/>
    </visual>
    <collision>
      <origin rpy="0 0 0" xyz="0.0 -0.65 -0.65"/>
      <geometry>
        <mesh filename="file:///home/user/proyecto_ws/src/proyecto_final/meshes/link6_1.stl" scale="0.001 0.001 0.001"/>
      </geometry>
    </collision>
  </link>
  <link name="gripper2_1">
    <inertial>
      <origin rpy="0 0 0" xyz="-0.005999999025635234 3.4301603779596235e-09 0.012459448647346716"/>
      <mass value="0.11617995373088826"/>
      <inertia ixx="4.7e-05" ixy="0.0" ixz="-0.0" iyy="1.7e-05" iyz="-0.0" izz="3.2e-05"/>
    </inertial>
    <visual>
      <origin rpy="0 0 0" xyz="-0.0 -0.65 -0.71"/>
      <geometry>
        <mesh filename="file:///home/user/proyecto_ws/src/proyecto_final/meshes/gripper2_1.stl" scale="0.001 0.001 0.001"/>
      </geometry>
      <material name="silver"/>
    </visual>
    <collision>
      <origin rpy="0 0 0" xyz="-0.0 -0.65 -0.71"/>
      <geometry>
        <mesh filename="file:///home/user/proyecto_ws/src/proyecto_final/meshes/gripper2_1.stl" scale="0.001 0.001 0.001"/>
      </geometry>
    </collision>
  </link>
  <link name="griper1_1">
    <inertial>
      <origin rpy="0 0 0" xyz="0.006000000974364768 3.4301603779596235e-09 0.012459448647346716"/>
      <mass value="0.11617995373088826"/>
      <inertia ixx="4.7e-05" ixy="0.0" ixz="-0.0" iyy="1.7e-05" iyz="-0.0" izz="3.2e-05"/>
    </inertial>
    <visual>
      <origin rpy="0 0 0" xyz="-0.0 -0.65 -0.71"/>
      <geometry>
        <mesh filename="file:///home/user/proyecto_ws/src/proyecto_final/meshes/griper1_1.stl" scale="0.001 0.001 0.001"/>
      </geometry>
      <material name="silver"/>
    </visual>
    <collision>
      <origin rpy="0 0 0" xyz="-0.0 -0.65 -0.71"/>
      <geometry>
        <mesh filename="file:///home/user/proyecto_ws/src/proyecto_final/meshes/griper1_1.stl" scale="0.001 0.001 0.001"/>
      </geometry>
    </collision>
  </link>
  <joint name="motor1" type="continuous">
    <origin rpy="0 0 0" xyz="0.0 0.05 0.0"/>
    <parent link="base_link"/>
    <child link="link1_1"/>
    <axis xyz="0.0 1.0 0.0"/>
  </joint>
  <joint name="motor2" type="continuous">
    <origin rpy="0 0 0" xyz="-0.0 0.05 0.1"/>
    <parent link="link1_1"/>
    <child link="link2_1"/>
    <axis xyz="0.0 0.0 1.0"/>
  </joint>
  <joint name="motor3" type="continuous">
    <origin rpy="0 0 0" xyz="0.0 0.1 0.2"/>
    <parent link="link2_1"/>
    <child link="link3_1"/>
    <axis xyz="0.0 1.0 0.0"/>
  </joint>
  <joint name="motor4" type="continuous">
    <origin rpy="0 0 0" xyz="-0.0 0.15 0.1"/>
    <parent link="link3_1"/>
    <child link="link4_1"/>
    <axis xyz="0.0 0.0 1.0"/>
  </joint>
  <joint name="motor5" type="continuous">
    <origin rpy="0 0 0" xyz="0.0 0.1 0.2"/>
    <parent link="link4_1"/>
    <child link="link5_1"/>
    <axis xyz="0.0 1.0 0.0"/>
  </joint>
  <joint name="motor6" type="continuous">
    <origin rpy="0 0 0" xyz="-0.0 0.2 0.05"/>
    <parent link="link5_1"/>
    <child link="link6_1"/>
    <axis xyz="0.0 0.0 1.0"/>
  </joint>
  <joint name="Corredera9" type="prismatic">
    <origin rpy="0 0 0" xyz="0.0 0.0 0.06"/>
    <parent link="link6_1"/>
    <child link="gripper2_1"/>
    <axis xyz="1.0 0.0 0.0"/>
    <limit effort="100" lower="-0.03" upper="-0.006" velocity="100"/>
  </joint>
  <joint name="Corredera10" type="prismatic">
    <origin rpy="0 0 0" xyz="0.0 0.0 0.06"/>
    <parent link="link6_1"/>
    <child link="griper1_1"/>
    <axis xyz="1.0 0.0 0.0"/>
    <limit effort="100" lower="0.006" upper="0.03" velocity="100"/>
  </joint>
</robot>

